[2025-04-28T09:51:55.637+0000] {scheduler_job_runner.py:1586} WARNING - Marking task instance <TaskInstance: update_energy_data_dag.run_update_energy_data scheduled__2025-04-27T12:00:00+00:00 [queued]> stuck in queued as failed. If the task instance has available retries, it will be retried.
[2025-04-28T09:51:56.081+0000] {scheduler_job_runner.py:781} ERROR - Executor reports task instance <TaskInstance: update_energy_data_dag.run_update_energy_data scheduled__2025-04-27T12:00:00+00:00 [queued]> finished (failed) although the task says it's queued. (Info: None) Was the task killed externally?
