[2025-04-28T17:48:12.090+0000] {taskinstance.py:1956} INFO - Dependencies all met for dep_context=non-requeueable deps ti=<TaskInstance: daily_forecast_dag.run_load_forecast manual__2025-04-28T17:48:08.955149+00:00 [queued]>
[2025-04-28T17:48:12.102+0000] {taskinstance.py:1956} INFO - Dependencies all met for dep_context=requeueable deps ti=<TaskInstance: daily_forecast_dag.run_load_forecast manual__2025-04-28T17:48:08.955149+00:00 [queued]>
[2025-04-28T17:48:12.102+0000] {taskinstance.py:2170} INFO - Starting attempt 1 of 1
[2025-04-28T17:48:12.121+0000] {taskinstance.py:2191} INFO - Executing <Task(PythonOperator): run_load_forecast> on 2025-04-28 17:48:08.955149+00:00
[2025-04-28T17:48:12.132+0000] {standard_task_runner.py:60} INFO - Started process 3430 to run task
[2025-04-28T17:48:12.137+0000] {standard_task_runner.py:87} INFO - Running: ['***', 'tasks', 'run', 'daily_forecast_dag', 'run_load_forecast', 'manual__2025-04-28T17:48:08.955149+00:00', '--job-id', '54', '--raw', '--subdir', 'DAGS_FOLDER/historical_predictions_dag.py.py', '--cfg-path', '/tmp/tmpd144ehia']
[2025-04-28T17:48:12.138+0000] {standard_task_runner.py:88} INFO - Job 54: Subtask run_load_forecast
[2025-04-28T17:48:12.241+0000] {task_command.py:423} INFO - Running <TaskInstance: daily_forecast_dag.run_load_forecast manual__2025-04-28T17:48:08.955149+00:00 [running]> on host 5464d109121d
[2025-04-28T17:48:12.435+0000] {taskinstance.py:2480} INFO - Exporting env vars: AIRFLOW_CTX_DAG_OWNER='***' AIRFLOW_CTX_DAG_ID='daily_forecast_dag' AIRFLOW_CTX_TASK_ID='run_load_forecast' AIRFLOW_CTX_EXECUTION_DATE='2025-04-28T17:48:08.955149+00:00' AIRFLOW_CTX_TRY_NUMBER='1' AIRFLOW_CTX_DAG_RUN_ID='manual__2025-04-28T17:48:08.955149+00:00'
[2025-04-28T17:48:14.175+0000] {taskinstance.py:2698} ERROR - Task failed with exception
Traceback (most recent call last):
  File "/home/airflow/.local/lib/python3.8/site-packages/pandas/core/indexes/base.py", line 3653, in get_loc
    return self._engine.get_loc(casted_key)
  File "pandas/_libs/index.pyx", line 147, in pandas._libs.index.IndexEngine.get_loc
  File "pandas/_libs/index.pyx", line 176, in pandas._libs.index.IndexEngine.get_loc
  File "pandas/_libs/hashtable_class_helper.pxi", line 7080, in pandas._libs.hashtable.PyObjectHashTable.get_item
  File "pandas/_libs/hashtable_class_helper.pxi", line 7088, in pandas._libs.hashtable.PyObjectHashTable.get_item
KeyError: 'T'

The above exception was the direct cause of the following exception:

Traceback (most recent call last):
  File "/home/airflow/.local/lib/python3.8/site-packages/airflow/models/taskinstance.py", line 433, in _execute_task
    result = execute_callable(context=context, **execute_callable_kwargs)
  File "/home/airflow/.local/lib/python3.8/site-packages/airflow/operators/python.py", line 199, in execute
    return_value = self.execute_callable()
  File "/home/airflow/.local/lib/python3.8/site-packages/airflow/operators/python.py", line 216, in execute_callable
    return self.python_callable(*self.op_args, **self.op_kwargs)
  File "/opt/airflow/dags/historical_predictions_dag.py.py", line 31, in forecast_task
    run_forecast_pipeline(
  File "/opt/airflow/dags/tasks/historical_predictions.py", line 126, in run_forecast_pipeline
    feature_df = build_feature_dataframe(raw_weather)
  File "/opt/airflow/dags/tasks/historical_predictions.py", line 60, in build_feature_dataframe
    df['heating_degree'] = (18 - df['T']).clip(lower=0)
  File "/home/airflow/.local/lib/python3.8/site-packages/pandas/core/frame.py", line 3761, in __getitem__
    indexer = self.columns.get_loc(key)
  File "/home/airflow/.local/lib/python3.8/site-packages/pandas/core/indexes/base.py", line 3655, in get_loc
    raise KeyError(key) from err
KeyError: 'T'
[2025-04-28T17:48:14.198+0000] {taskinstance.py:1138} INFO - Marking task as FAILED. dag_id=daily_forecast_dag, task_id=run_load_forecast, execution_date=20250428T174808, start_date=20250428T174812, end_date=20250428T174814
[2025-04-28T17:48:14.224+0000] {standard_task_runner.py:107} ERROR - Failed to execute job 54 for task run_load_forecast ('T'; 3430)
[2025-04-28T17:48:14.279+0000] {local_task_job_runner.py:234} INFO - Task exited with return code 1
[2025-04-28T17:48:14.324+0000] {taskinstance.py:3280} INFO - 0 downstream tasks scheduled from follow-on schedule check
