[2025-04-28T18:01:28.710+0000] {taskinstance.py:1956} INFO - Dependencies all met for dep_context=non-requeueable deps ti=<TaskInstance: daily_forecast_dag.run_load_forecast manual__2025-04-28T18:01:26.643100+00:00 [queued]>
[2025-04-28T18:01:28.722+0000] {taskinstance.py:1956} INFO - Dependencies all met for dep_context=requeueable deps ti=<TaskInstance: daily_forecast_dag.run_load_forecast manual__2025-04-28T18:01:26.643100+00:00 [queued]>
[2025-04-28T18:01:28.722+0000] {taskinstance.py:2170} INFO - Starting attempt 1 of 1
[2025-04-28T18:01:28.739+0000] {taskinstance.py:2191} INFO - Executing <Task(PythonOperator): run_load_forecast> on 2025-04-28 18:01:26.643100+00:00
[2025-04-28T18:01:28.749+0000] {standard_task_runner.py:60} INFO - Started process 3873 to run task
[2025-04-28T18:01:28.754+0000] {standard_task_runner.py:87} INFO - Running: ['***', 'tasks', 'run', 'daily_forecast_dag', 'run_load_forecast', 'manual__2025-04-28T18:01:26.643100+00:00', '--job-id', '61', '--raw', '--subdir', 'DAGS_FOLDER/historical_predictions_dag.py.py', '--cfg-path', '/tmp/tmpdp4recv8']
[2025-04-28T18:01:28.756+0000] {standard_task_runner.py:88} INFO - Job 61: Subtask run_load_forecast
[2025-04-28T18:01:28.822+0000] {task_command.py:423} INFO - Running <TaskInstance: daily_forecast_dag.run_load_forecast manual__2025-04-28T18:01:26.643100+00:00 [running]> on host 5464d109121d
[2025-04-28T18:01:28.941+0000] {taskinstance.py:2480} INFO - Exporting env vars: AIRFLOW_CTX_DAG_OWNER='***' AIRFLOW_CTX_DAG_ID='daily_forecast_dag' AIRFLOW_CTX_TASK_ID='run_load_forecast' AIRFLOW_CTX_EXECUTION_DATE='2025-04-28T18:01:26.643100+00:00' AIRFLOW_CTX_TRY_NUMBER='1' AIRFLOW_CTX_DAG_RUN_ID='manual__2025-04-28T18:01:26.643100+00:00'
[2025-04-28T18:01:30.721+0000] {logging_mixin.py:188} INFO - Index(['timestamp', 'stn', 'dd', 'fh', 'ff', 'fx', 't', 't10n', 'td', 'sq',
       'q', 'dr', 'rh', 'p', 'vv', 'n', 'u', 'ww', 'ix', 'm', 'r', 's', 'o',
       'y', 'T', 'hour', 'day_of_week', 'month', 'is_weekend', 'is_holiday'],
      dtype='object')
[2025-04-28T18:01:30.810+0000] {warnings.py:109} WARNING - /home/***/.local/lib/python3.8/site-packages/xgboost/core.py:158: UserWarning: [18:01:30] WARNING: /workspace/src/collective/../data/../common/error_msg.h:80: If you are loading a serialized model (like pickle in Python, RDS in R) or
configuration generated by an older version of XGBoost, please export the model by calling
`Booster.save_model` from that version first, then load it back in current version. See:

    https://xgboost.readthedocs.io/en/stable/tutorials/saving_model.html

for more details about differences between saving model and serializing.

  warnings.warn(smsg, UserWarning)

[2025-04-28T18:01:30.887+0000] {logging_mixin.py:188} INFO - ‚ùå Error: column "index" of relation "historical_load_predictions" does not exist
LINE 2: ...SERT INTO "public"."historical_load_predictions" (index, tim...
                                                             ^
[2025-04-28T18:01:30.900+0000] {python.py:201} INFO - Done. Returned value was: None
[2025-04-28T18:01:30.928+0000] {taskinstance.py:1138} INFO - Marking task as SUCCESS. dag_id=daily_forecast_dag, task_id=run_load_forecast, execution_date=20250428T180126, start_date=20250428T180128, end_date=20250428T180130
[2025-04-28T18:01:31.023+0000] {local_task_job_runner.py:234} INFO - Task exited with return code 0
[2025-04-28T18:01:31.081+0000] {taskinstance.py:3280} INFO - 0 downstream tasks scheduled from follow-on schedule check
