[2025-04-28T17:59:30.292+0000] {taskinstance.py:1956} INFO - Dependencies all met for dep_context=non-requeueable deps ti=<TaskInstance: daily_forecast_dag.run_load_forecast manual__2025-04-28T17:59:27.874215+00:00 [queued]>
[2025-04-28T17:59:30.303+0000] {taskinstance.py:1956} INFO - Dependencies all met for dep_context=requeueable deps ti=<TaskInstance: daily_forecast_dag.run_load_forecast manual__2025-04-28T17:59:27.874215+00:00 [queued]>
[2025-04-28T17:59:30.303+0000] {taskinstance.py:2170} INFO - Starting attempt 1 of 1
[2025-04-28T17:59:30.320+0000] {taskinstance.py:2191} INFO - Executing <Task(PythonOperator): run_load_forecast> on 2025-04-28 17:59:27.874215+00:00
[2025-04-28T17:59:30.332+0000] {standard_task_runner.py:60} INFO - Started process 3812 to run task
[2025-04-28T17:59:30.336+0000] {standard_task_runner.py:87} INFO - Running: ['***', 'tasks', 'run', 'daily_forecast_dag', 'run_load_forecast', 'manual__2025-04-28T17:59:27.874215+00:00', '--job-id', '60', '--raw', '--subdir', 'DAGS_FOLDER/historical_predictions_dag.py.py', '--cfg-path', '/tmp/tmplf1z91cd']
[2025-04-28T17:59:30.338+0000] {standard_task_runner.py:88} INFO - Job 60: Subtask run_load_forecast
[2025-04-28T17:59:30.401+0000] {task_command.py:423} INFO - Running <TaskInstance: daily_forecast_dag.run_load_forecast manual__2025-04-28T17:59:27.874215+00:00 [running]> on host 5464d109121d
[2025-04-28T17:59:30.505+0000] {taskinstance.py:2480} INFO - Exporting env vars: AIRFLOW_CTX_DAG_OWNER='***' AIRFLOW_CTX_DAG_ID='daily_forecast_dag' AIRFLOW_CTX_TASK_ID='run_load_forecast' AIRFLOW_CTX_EXECUTION_DATE='2025-04-28T17:59:27.874215+00:00' AIRFLOW_CTX_TRY_NUMBER='1' AIRFLOW_CTX_DAG_RUN_ID='manual__2025-04-28T17:59:27.874215+00:00'
[2025-04-28T17:59:32.236+0000] {logging_mixin.py:188} INFO - Index(['timestamp', 'stn', 'dd', 'fh', 'ff', 'fx', 't', 't10n', 'td', 'sq',
       'q', 'dr', 'rh', 'p', 'vv', 'n', 'u', 'ww', 'ix', 'm', 'r', 's', 'o',
       'y', 'T', 'hour', 'day_of_week', 'month', 'is_weekend', 'is_holiday'],
      dtype='object')
[2025-04-28T17:59:32.308+0000] {warnings.py:109} WARNING - /home/***/.local/lib/python3.8/site-packages/xgboost/core.py:158: UserWarning: [17:59:32] WARNING: /workspace/src/collective/../data/../common/error_msg.h:80: If you are loading a serialized model (like pickle in Python, RDS in R) or
configuration generated by an older version of XGBoost, please export the model by calling
`Booster.save_model` from that version first, then load it back in current version. See:

    https://xgboost.readthedocs.io/en/stable/tutorials/saving_model.html

for more details about differences between saving model and serializing.

  warnings.warn(smsg, UserWarning)

[2025-04-28T17:59:32.363+0000] {taskinstance.py:2698} ERROR - Task failed with exception
Traceback (most recent call last):
  File "/home/airflow/.local/lib/python3.8/site-packages/airflow/models/taskinstance.py", line 433, in _execute_task
    result = execute_callable(context=context, **execute_callable_kwargs)
  File "/home/airflow/.local/lib/python3.8/site-packages/airflow/operators/python.py", line 199, in execute
    return_value = self.execute_callable()
  File "/home/airflow/.local/lib/python3.8/site-packages/airflow/operators/python.py", line 216, in execute_callable
    return self.python_callable(*self.op_args, **self.op_kwargs)
  File "/opt/airflow/dags/historical_predictions_dag.py.py", line 31, in forecast_task
    run_forecast_pipeline(
  File "/opt/airflow/dags/tasks/historical_predictions.py", line 142, in run_forecast_pipeline
    write_predictions_to_db(predictions, prediction_table, db_config)
  File "/opt/airflow/dags/tasks/historical_predictions.py", line 99, in write_predictions_to_db
    sql.upsert_dataframe(
TypeError: upsert_dataframe() got an unexpected keyword argument 'df_data'
[2025-04-28T17:59:32.375+0000] {taskinstance.py:1138} INFO - Marking task as FAILED. dag_id=daily_forecast_dag, task_id=run_load_forecast, execution_date=20250428T175927, start_date=20250428T175930, end_date=20250428T175932
[2025-04-28T17:59:32.392+0000] {standard_task_runner.py:107} ERROR - Failed to execute job 60 for task run_load_forecast (upsert_dataframe() got an unexpected keyword argument 'df_data'; 3812)
[2025-04-28T17:59:32.441+0000] {local_task_job_runner.py:234} INFO - Task exited with return code 1
[2025-04-28T17:59:32.481+0000] {taskinstance.py:3280} INFO - 0 downstream tasks scheduled from follow-on schedule check
