[2025-04-28T15:33:54.243+0000] {taskinstance.py:1956} INFO - Dependencies all met for dep_context=non-requeueable deps ti=<TaskInstance: daily_forecast_dag.run_load_forecast manual__2025-04-28T15:32:49.305591+00:00 [queued]>
[2025-04-28T15:33:54.251+0000] {taskinstance.py:1956} INFO - Dependencies all met for dep_context=requeueable deps ti=<TaskInstance: daily_forecast_dag.run_load_forecast manual__2025-04-28T15:32:49.305591+00:00 [queued]>
[2025-04-28T15:33:54.251+0000] {taskinstance.py:2170} INFO - Starting attempt 2 of 2
[2025-04-28T15:33:54.266+0000] {taskinstance.py:2191} INFO - Executing <Task(PythonOperator): run_load_forecast> on 2025-04-28 15:32:49.305591+00:00
[2025-04-28T15:33:54.275+0000] {standard_task_runner.py:60} INFO - Started process 465 to run task
[2025-04-28T15:33:54.279+0000] {standard_task_runner.py:87} INFO - Running: ['***', 'tasks', 'run', 'daily_forecast_dag', 'run_load_forecast', 'manual__2025-04-28T15:32:49.305591+00:00', '--job-id', '43', '--raw', '--subdir', 'DAGS_FOLDER/historical_predictions_dag.py.py', '--cfg-path', '/tmp/tmp3991y4v2']
[2025-04-28T15:33:54.280+0000] {standard_task_runner.py:88} INFO - Job 43: Subtask run_load_forecast
[2025-04-28T15:33:54.329+0000] {task_command.py:423} INFO - Running <TaskInstance: daily_forecast_dag.run_load_forecast manual__2025-04-28T15:32:49.305591+00:00 [running]> on host 926a5f6962f9
[2025-04-28T15:33:54.403+0000] {taskinstance.py:2480} INFO - Exporting env vars: AIRFLOW_CTX_DAG_OWNER='***' AIRFLOW_CTX_DAG_ID='daily_forecast_dag' AIRFLOW_CTX_TASK_ID='run_load_forecast' AIRFLOW_CTX_EXECUTION_DATE='2025-04-28T15:32:49.305591+00:00' AIRFLOW_CTX_TRY_NUMBER='2' AIRFLOW_CTX_DAG_RUN_ID='manual__2025-04-28T15:32:49.305591+00:00'
[2025-04-28T15:33:54.892+0000] {taskinstance.py:2698} ERROR - Task failed with exception
Traceback (most recent call last):
  File "/home/airflow/.local/lib/python3.8/site-packages/airflow/models/taskinstance.py", line 433, in _execute_task
    result = execute_callable(context=context, **execute_callable_kwargs)
  File "/home/airflow/.local/lib/python3.8/site-packages/airflow/operators/python.py", line 199, in execute
    return_value = self.execute_callable()
  File "/home/airflow/.local/lib/python3.8/site-packages/airflow/operators/python.py", line 216, in execute_callable
    return self.python_callable(*self.op_args, **self.op_kwargs)
  File "/opt/airflow/dags/historical_predictions_dag.py.py", line 31, in forecast_task
    run_forecast_pipeline(
  File "/opt/airflow/dags/tasks/historical_predictions.py", line 103, in run_forecast_pipeline
    feature_df = build_feature_dataframe(raw_weather)
  File "/opt/airflow/dags/tasks/historical_predictions.py", line 29, in build_feature_dataframe
    df['hour'] = df.index.hour
AttributeError: 'RangeIndex' object has no attribute 'hour'
[2025-04-28T15:33:54.904+0000] {taskinstance.py:1138} INFO - Marking task as FAILED. dag_id=daily_forecast_dag, task_id=run_load_forecast, execution_date=20250428T153249, start_date=20250428T153354, end_date=20250428T153354
[2025-04-28T15:33:54.927+0000] {standard_task_runner.py:107} ERROR - Failed to execute job 43 for task run_load_forecast ('RangeIndex' object has no attribute 'hour'; 465)
[2025-04-28T15:33:54.973+0000] {local_task_job_runner.py:234} INFO - Task exited with return code 1
[2025-04-28T15:33:55.000+0000] {taskinstance.py:3280} INFO - 0 downstream tasks scheduled from follow-on schedule check
