[2025-04-28T17:57:43.525+0000] {taskinstance.py:1956} INFO - Dependencies all met for dep_context=non-requeueable deps ti=<TaskInstance: daily_forecast_dag.run_load_forecast manual__2025-04-28T17:57:40.491740+00:00 [queued]>
[2025-04-28T17:57:43.541+0000] {taskinstance.py:1956} INFO - Dependencies all met for dep_context=requeueable deps ti=<TaskInstance: daily_forecast_dag.run_load_forecast manual__2025-04-28T17:57:40.491740+00:00 [queued]>
[2025-04-28T17:57:43.542+0000] {taskinstance.py:2170} INFO - Starting attempt 1 of 1
[2025-04-28T17:57:43.561+0000] {taskinstance.py:2191} INFO - Executing <Task(PythonOperator): run_load_forecast> on 2025-04-28 17:57:40.491740+00:00
[2025-04-28T17:57:43.574+0000] {standard_task_runner.py:60} INFO - Started process 3724 to run task
[2025-04-28T17:57:43.579+0000] {standard_task_runner.py:87} INFO - Running: ['***', 'tasks', 'run', 'daily_forecast_dag', 'run_load_forecast', 'manual__2025-04-28T17:57:40.491740+00:00', '--job-id', '57', '--raw', '--subdir', 'DAGS_FOLDER/historical_predictions_dag.py.py', '--cfg-path', '/tmp/tmpj6tdy7dh']
[2025-04-28T17:57:43.582+0000] {standard_task_runner.py:88} INFO - Job 57: Subtask run_load_forecast
[2025-04-28T17:57:43.658+0000] {task_command.py:423} INFO - Running <TaskInstance: daily_forecast_dag.run_load_forecast manual__2025-04-28T17:57:40.491740+00:00 [running]> on host 5464d109121d
[2025-04-28T17:57:43.805+0000] {taskinstance.py:2480} INFO - Exporting env vars: AIRFLOW_CTX_DAG_OWNER='***' AIRFLOW_CTX_DAG_ID='daily_forecast_dag' AIRFLOW_CTX_TASK_ID='run_load_forecast' AIRFLOW_CTX_EXECUTION_DATE='2025-04-28T17:57:40.491740+00:00' AIRFLOW_CTX_TRY_NUMBER='1' AIRFLOW_CTX_DAG_RUN_ID='manual__2025-04-28T17:57:40.491740+00:00'
[2025-04-28T17:57:45.311+0000] {logging_mixin.py:188} INFO - Index(['timestamp', 'stn', 'dd', 'fh', 'ff', 'fx', 't', 't10n', 'td', 'sq',
       'q', 'dr', 'rh', 'p', 'vv', 'n', 'u', 'ww', 'ix', 'm', 'r', 's', 'o',
       'y', 'hour', 'day_of_week', 'month', 'is_weekend', 'is_holiday'],
      dtype='object')
[2025-04-28T17:57:45.681+0000] {warnings.py:109} WARNING - /home/***/.local/lib/python3.8/site-packages/xgboost/core.py:158: UserWarning: [17:57:45] WARNING: /workspace/src/collective/../data/../common/error_msg.h:80: If you are loading a serialized model (like pickle in Python, RDS in R) or
configuration generated by an older version of XGBoost, please export the model by calling
`Booster.save_model` from that version first, then load it back in current version. See:

    https://xgboost.readthedocs.io/en/stable/tutorials/saving_model.html

for more details about differences between saving model and serializing.

  warnings.warn(smsg, UserWarning)

[2025-04-28T17:57:45.799+0000] {taskinstance.py:2698} ERROR - Task failed with exception
Traceback (most recent call last):
  File "/home/airflow/.local/lib/python3.8/site-packages/airflow/models/taskinstance.py", line 433, in _execute_task
    result = execute_callable(context=context, **execute_callable_kwargs)
  File "/home/airflow/.local/lib/python3.8/site-packages/airflow/operators/python.py", line 199, in execute
    return_value = self.execute_callable()
  File "/home/airflow/.local/lib/python3.8/site-packages/airflow/operators/python.py", line 216, in execute_callable
    return self.python_callable(*self.op_args, **self.op_kwargs)
  File "/opt/airflow/dags/historical_predictions_dag.py.py", line 31, in forecast_task
    run_forecast_pipeline(
  File "/opt/airflow/dags/tasks/historical_predictions.py", line 134, in run_forecast_pipeline
    predictions = predict_load(feature_df, model)
  File "/opt/airflow/dags/tasks/historical_predictions.py", line 85, in predict_load
    preds = model.predict(X)
  File "/home/airflow/.local/lib/python3.8/site-packages/xgboost/sklearn.py", line 1248, in predict
    predts = self.get_booster().inplace_predict(
  File "/home/airflow/.local/lib/python3.8/site-packages/xgboost/core.py", line 2514, in inplace_predict
    self._validate_features(fns)
  File "/home/airflow/.local/lib/python3.8/site-packages/xgboost/core.py", line 3079, in _validate_features
    raise ValueError(msg.format(self.feature_names, feature_names))
ValueError: feature_names mismatch: ['hour', 'day_of_week', 'month', 'is_weekend', 'is_holiday', 'T', 'heating_degree', 'cooling_degree'] ['hour', 'day_of_week', 'month', 'is_weekend', 'is_holiday', 't', 'heating_degree', 'cooling_degree']
expected T in input data
training data did not have the following fields: t
[2025-04-28T17:57:45.810+0000] {taskinstance.py:1138} INFO - Marking task as FAILED. dag_id=daily_forecast_dag, task_id=run_load_forecast, execution_date=20250428T175740, start_date=20250428T175743, end_date=20250428T175745
[2025-04-28T17:57:45.871+0000] {standard_task_runner.py:107} ERROR - Failed to execute job 57 for task run_load_forecast (feature_names mismatch: ['hour', 'day_of_week', 'month', 'is_weekend', 'is_holiday', 'T', 'heating_degree', 'cooling_degree'] ['hour', 'day_of_week', 'month', 'is_weekend', 'is_holiday', 't', 'heating_degree', 'cooling_degree']
expected T in input data
training data did not have the following fields: t; 3724)
[2025-04-28T17:57:45.952+0000] {local_task_job_runner.py:234} INFO - Task exited with return code 1
[2025-04-28T17:57:46.028+0000] {taskinstance.py:3280} INFO - 0 downstream tasks scheduled from follow-on schedule check
