[2025-04-28T15:24:03.443+0000] {taskinstance.py:1956} INFO - Dependencies all met for dep_context=non-requeueable deps ti=<TaskInstance: daily_forecast_dag.run_load_forecast scheduled__2025-04-27T05:00:00+00:00 [queued]>
[2025-04-28T15:24:03.457+0000] {taskinstance.py:1956} INFO - Dependencies all met for dep_context=requeueable deps ti=<TaskInstance: daily_forecast_dag.run_load_forecast scheduled__2025-04-27T05:00:00+00:00 [queued]>
[2025-04-28T15:24:03.458+0000] {taskinstance.py:2170} INFO - Starting attempt 1 of 2
[2025-04-28T15:24:03.479+0000] {taskinstance.py:2191} INFO - Executing <Task(PythonOperator): run_load_forecast> on 2025-04-27 05:00:00+00:00
[2025-04-28T15:24:03.495+0000] {standard_task_runner.py:60} INFO - Started process 147 to run task
[2025-04-28T15:24:03.499+0000] {standard_task_runner.py:87} INFO - Running: ['***', 'tasks', 'run', 'daily_forecast_dag', 'run_load_forecast', 'scheduled__2025-04-27T05:00:00+00:00', '--job-id', '38', '--raw', '--subdir', 'DAGS_FOLDER/historical_predictions_dag.py.py', '--cfg-path', '/tmp/tmpkfmjevt_']
[2025-04-28T15:24:03.501+0000] {standard_task_runner.py:88} INFO - Job 38: Subtask run_load_forecast
[2025-04-28T15:24:03.584+0000] {task_command.py:423} INFO - Running <TaskInstance: daily_forecast_dag.run_load_forecast scheduled__2025-04-27T05:00:00+00:00 [running]> on host 926a5f6962f9
[2025-04-28T15:24:03.691+0000] {taskinstance.py:2480} INFO - Exporting env vars: AIRFLOW_CTX_DAG_OWNER='***' AIRFLOW_CTX_DAG_ID='daily_forecast_dag' AIRFLOW_CTX_TASK_ID='run_load_forecast' AIRFLOW_CTX_EXECUTION_DATE='2025-04-27T05:00:00+00:00' AIRFLOW_CTX_TRY_NUMBER='1' AIRFLOW_CTX_DAG_RUN_ID='scheduled__2025-04-27T05:00:00+00:00'
[2025-04-28T15:24:03.692+0000] {taskinstance.py:2698} ERROR - Task failed with exception
Traceback (most recent call last):
  File "/home/airflow/.local/lib/python3.8/site-packages/airflow/models/taskinstance.py", line 433, in _execute_task
    result = execute_callable(context=context, **execute_callable_kwargs)
  File "/home/airflow/.local/lib/python3.8/site-packages/airflow/operators/python.py", line 199, in execute
    return_value = self.execute_callable()
  File "/home/airflow/.local/lib/python3.8/site-packages/airflow/operators/python.py", line 216, in execute_callable
    return self.python_callable(*self.op_args, **self.op_kwargs)
  File "/opt/airflow/dags/historical_predictions_dag.py.py", line 31, in forecast_task
    run_forecast_pipeline(
  File "/opt/airflow/dags/tasks/historical_predictions.py", line 100, in run_forecast_pipeline
    raw_weather = get_weather_data(weather_table)
  File "/opt/airflow/dags/tasks/historical_predictions.py", line 20, in get_weather_data
    df = sql.load_table(table_name)
NameError: name 'sql' is not defined
[2025-04-28T15:24:03.706+0000] {taskinstance.py:1138} INFO - Marking task as UP_FOR_RETRY. dag_id=daily_forecast_dag, task_id=run_load_forecast, execution_date=20250427T050000, start_date=20250428T152403, end_date=20250428T152403
[2025-04-28T15:24:03.723+0000] {standard_task_runner.py:107} ERROR - Failed to execute job 38 for task run_load_forecast (name 'sql' is not defined; 147)
[2025-04-28T15:24:03.753+0000] {local_task_job_runner.py:234} INFO - Task exited with return code 1
[2025-04-28T15:24:03.776+0000] {taskinstance.py:3280} INFO - 0 downstream tasks scheduled from follow-on schedule check
