[2025-04-29T02:00:04.202+0000] {taskinstance.py:1956} INFO - Dependencies all met for dep_context=non-requeueable deps ti=<TaskInstance: hourly_forecast_dag.run_future_load_forecast scheduled__2025-04-29T01:00:00+00:00 [queued]>
[2025-04-29T02:00:04.237+0000] {taskinstance.py:1956} INFO - Dependencies all met for dep_context=requeueable deps ti=<TaskInstance: hourly_forecast_dag.run_future_load_forecast scheduled__2025-04-29T01:00:00+00:00 [queued]>
[2025-04-29T02:00:04.238+0000] {taskinstance.py:2170} INFO - Starting attempt 1 of 2
[2025-04-29T02:00:04.286+0000] {taskinstance.py:2191} INFO - Executing <Task(PythonOperator): run_future_load_forecast> on 2025-04-29 01:00:00+00:00
[2025-04-29T02:00:04.314+0000] {standard_task_runner.py:60} INFO - Started process 6871 to run task
[2025-04-29T02:00:04.326+0000] {standard_task_runner.py:87} INFO - Running: ['***', 'tasks', 'run', 'hourly_forecast_dag', 'run_future_load_forecast', 'scheduled__2025-04-29T01:00:00+00:00', '--job-id', '84', '--raw', '--subdir', 'DAGS_FOLDER/forecast_dag.py', '--cfg-path', '/tmp/tmp4hx0bcq2']
[2025-04-29T02:00:04.331+0000] {standard_task_runner.py:88} INFO - Job 84: Subtask run_future_load_forecast
[2025-04-29T02:00:04.490+0000] {task_command.py:423} INFO - Running <TaskInstance: hourly_forecast_dag.run_future_load_forecast scheduled__2025-04-29T01:00:00+00:00 [running]> on host 58c0d1847783
[2025-04-29T02:00:04.740+0000] {taskinstance.py:2480} INFO - Exporting env vars: AIRFLOW_CTX_DAG_OWNER='***' AIRFLOW_CTX_DAG_ID='hourly_forecast_dag' AIRFLOW_CTX_TASK_ID='run_future_load_forecast' AIRFLOW_CTX_EXECUTION_DATE='2025-04-29T01:00:00+00:00' AIRFLOW_CTX_TRY_NUMBER='1' AIRFLOW_CTX_DAG_RUN_ID='scheduled__2025-04-29T01:00:00+00:00'
[2025-04-29T02:02:17.756+0000] {taskinstance.py:2698} ERROR - Task failed with exception
Traceback (most recent call last):
  File "/home/airflow/.local/lib/python3.8/site-packages/urllib3/connection.py", line 174, in _new_conn
    conn = connection.create_connection(
  File "/home/airflow/.local/lib/python3.8/site-packages/urllib3/util/connection.py", line 95, in create_connection
    raise err
  File "/home/airflow/.local/lib/python3.8/site-packages/urllib3/util/connection.py", line 85, in create_connection
    sock.connect(sa)
OSError: [Errno 101] Network is unreachable

During handling of the above exception, another exception occurred:

Traceback (most recent call last):
  File "/home/airflow/.local/lib/python3.8/site-packages/urllib3/connectionpool.py", line 715, in urlopen
    httplib_response = self._make_request(
  File "/home/airflow/.local/lib/python3.8/site-packages/urllib3/connectionpool.py", line 404, in _make_request
    self._validate_conn(conn)
  File "/home/airflow/.local/lib/python3.8/site-packages/urllib3/connectionpool.py", line 1058, in _validate_conn
    conn.connect()
  File "/home/airflow/.local/lib/python3.8/site-packages/urllib3/connection.py", line 363, in connect
    self.sock = conn = self._new_conn()
  File "/home/airflow/.local/lib/python3.8/site-packages/urllib3/connection.py", line 186, in _new_conn
    raise NewConnectionError(
urllib3.exceptions.NewConnectionError: <urllib3.connection.HTTPSConnection object at 0x7e95891334c0>: Failed to establish a new connection: [Errno 101] Network is unreachable

During handling of the above exception, another exception occurred:

Traceback (most recent call last):
  File "/home/airflow/.local/lib/python3.8/site-packages/requests/adapters.py", line 486, in send
    resp = conn.urlopen(
  File "/home/airflow/.local/lib/python3.8/site-packages/urllib3/connectionpool.py", line 799, in urlopen
    retries = retries.increment(
  File "/home/airflow/.local/lib/python3.8/site-packages/urllib3/util/retry.py", line 592, in increment
    raise MaxRetryError(_pool, url, error or ResponseError(cause))
urllib3.exceptions.MaxRetryError: HTTPSConnectionPool(host='api.open-meteo.com', port=443): Max retries exceeded with url: /v1/forecast?latitude=52.1&longitude=5.18&hourly=temperature_2m,precipitation,shortwave_radiation,direct_radiation,diffuse_radiation,wind_speed_10m,wind_direction_10m,wind_gusts_10m (Caused by NewConnectionError('<urllib3.connection.HTTPSConnection object at 0x7e95891334c0>: Failed to establish a new connection: [Errno 101] Network is unreachable'))

During handling of the above exception, another exception occurred:

Traceback (most recent call last):
  File "/home/airflow/.local/lib/python3.8/site-packages/airflow/models/taskinstance.py", line 433, in _execute_task
    result = execute_callable(context=context, **execute_callable_kwargs)
  File "/home/airflow/.local/lib/python3.8/site-packages/airflow/operators/python.py", line 199, in execute
    return_value = self.execute_callable()
  File "/home/airflow/.local/lib/python3.8/site-packages/airflow/operators/python.py", line 216, in execute_callable
    return self.python_callable(*self.op_args, **self.op_kwargs)
  File "/opt/airflow/dags/tasks/forecast.py", line 35, in future_forecast_task
    resp = requests.get(OPEN_METEO_URL)
  File "/home/airflow/.local/lib/python3.8/site-packages/requests/api.py", line 73, in get
    return request("get", url, params=params, **kwargs)
  File "/home/airflow/.local/lib/python3.8/site-packages/requests/api.py", line 59, in request
    return session.request(method=method, url=url, **kwargs)
  File "/home/airflow/.local/lib/python3.8/site-packages/requests/sessions.py", line 589, in request
    resp = self.send(prep, **send_kwargs)
  File "/home/airflow/.local/lib/python3.8/site-packages/requests/sessions.py", line 703, in send
    r = adapter.send(request, **kwargs)
  File "/home/airflow/.local/lib/python3.8/site-packages/requests/adapters.py", line 519, in send
    raise ConnectionError(e, request=request)
requests.exceptions.ConnectionError: HTTPSConnectionPool(host='api.open-meteo.com', port=443): Max retries exceeded with url: /v1/forecast?latitude=52.1&longitude=5.18&hourly=temperature_2m,precipitation,shortwave_radiation,direct_radiation,diffuse_radiation,wind_speed_10m,wind_direction_10m,wind_gusts_10m (Caused by NewConnectionError('<urllib3.connection.HTTPSConnection object at 0x7e95891334c0>: Failed to establish a new connection: [Errno 101] Network is unreachable'))
[2025-04-29T02:02:17.815+0000] {taskinstance.py:1138} INFO - Marking task as UP_FOR_RETRY. dag_id=hourly_forecast_dag, task_id=run_future_load_forecast, execution_date=20250429T010000, start_date=20250429T020004, end_date=20250429T020217
[2025-04-29T02:02:17.866+0000] {standard_task_runner.py:107} ERROR - Failed to execute job 84 for task run_future_load_forecast (HTTPSConnectionPool(host='api.open-meteo.com', port=443): Max retries exceeded with url: /v1/forecast?latitude=52.1&longitude=5.18&hourly=temperature_2m,precipitation,shortwave_radiation,direct_radiation,diffuse_radiation,wind_speed_10m,wind_direction_10m,wind_gusts_10m (Caused by NewConnectionError('<urllib3.connection.HTTPSConnection object at 0x7e95891334c0>: Failed to establish a new connection: [Errno 101] Network is unreachable')); 6871)
[2025-04-29T02:02:17.925+0000] {local_task_job_runner.py:234} INFO - Task exited with return code 1
[2025-04-29T02:02:17.988+0000] {taskinstance.py:3280} INFO - 0 downstream tasks scheduled from follow-on schedule check
